Workbook

Sheet özet
D3: Kasım 2024'ten İtibaren Toplam Değerler | J3: Tamamlanan Sprint Değerleri
C4: Ürünler | D4: Toplam İş Adedi (Açık ve Kapalı Tüm Maddeleri, Bug Dahil) | E4: Toplam Bug Adedi | F4: Tamamlanan İş Adetleri | G4: Product Backlog Eritme oranı | J4: Tamamlanan Sprint içinde Üzerinde Çalışılan İş Adedi (Bug Dahil) | K4: Tamamlanan Sprint içinde Üzerinde Çalışılan Bug Adedi | L4: Tamamlanan İş Adetleri | M4: Tamamlanan Sprint Perf. Oranı
C5: CRM | D5: =VLOOKUP(C5,'Ürün İş Listesi'!$P$30:$Z$50,8,0) -> 152 | E5: =VLOOKUP(C5,'Ürün İş Listesi'!$AQ$32:$AR$48,2,0) -> 10 | F5: =G5*D5 -> 128 | G5: =VLOOKUP(C5,'Ürün İş Listesi'!$P$30:$Z$50,11,0) -> 0.84210526 | J5: =IFERROR(VLOOKUP(C5,'Ürün İş Listesi'!$AQ$5:$AT$23,4,0),"") -> 27 | K5: =IFERROR(VLOOKUP(C5,'Ürün İş Listesi'!$AQ$5:$AR$23,2,0),"") -> 0 | L5: =IFERROR(M5*J5,"-") -> 23 | M5: =IFERROR(VLOOKUP(C5,'Ürün İş Listesi'!$P$5:$Z$23,11,0),"") -> 0.85185185
C6: Destek Portal | D6: =VLOOKUP(C6,'Ürün İş Listesi'!$P$30:$Z$50,8,0) -> 29 | E6: =VLOOKUP(C6,'Ürün İş Listesi'!$AQ$32:$AR$48,2,0) -> 11 | F6: =G6*D6 -> 26 | G6: =VLOOKUP(C6,'Ürün İş Listesi'!$P$30:$Z$50,11,0) -> 0.89655172 | J6: =IFERROR(VLOOKUP(C6,'Ürün İş Listesi'!$AQ$5:$AT$23,4,0),"") -> 1 | K6: =IFERROR(VLOOKUP(C6,'Ürün İş Listesi'!$AQ$5:$AR$23,2,0),"") -> 0 | L6: =IFERROR(M6*J6,"-") -> - | M6: =IFERROR(VLOOKUP(C6,'Ürün İş Listesi'!$P$5:$Z$23,11,0),"")
C7: E-Defter | D7: =VLOOKUP(C7,'Ürün İş Listesi'!$P$30:$Z$50,8,0) -> 26 | E7: =VLOOKUP(C7,'Ürün İş Listesi'!$AQ$32:$AR$48,2,0) -> 12 | F7: =G7*D7 -> 26 | G7: =VLOOKUP(C7,'Ürün İş Listesi'!$P$30:$Z$50,11,0) -> 1 | J7: =IFERROR(VLOOKUP(C7,'Ürün İş Listesi'!$AQ$5:$AT$23,4,0),"") -> 5 | K7: =IFERROR(VLOOKUP(C7,'Ürün İş Listesi'!$AQ$5:$AR$23,2,0),"") -> 1 | L7: =IFERROR(M7*J7,"-") -> 2 | M7: =IFERROR(VLOOKUP(C7,'Ürün İş Listesi'!$P$5:$Z$23,11,0),"") -> 0.4
C8: E-Fatura | D8: =VLOOKUP(C8,'Ürün İş Listesi'!$P$30:$Z$50,8,0) -> 127 | E8: =VLOOKUP(C8,'Ürün İş Listesi'!$AQ$32:$AR$48,2,0) -> 39 | F8: =G8*D8 -> 108 | G8: =VLOOKUP(C8,'Ürün İş Listesi'!$P$30:$Z$50,11,0) -> 0.8503937 | J8: =IFERROR(VLOOKUP(C8,'Ürün İş Listesi'!$AQ$5:$AT$23,4,0),"") -> 5 | K8: =IFERROR(VLOOKUP(C8,'Ürün İş Listesi'!$AQ$5:$AR$23,2,0),"") -> 1 | L8: =IFERROR(M8*J8,"-") -> 2 | M8: =IFERROR(VLOOKUP(C8,'Ürün İş Listesi'!$P$5:$Z$23,11,0),"") -> 0.4
C9: Entegrasyon Suit | D9: =VLOOKUP(C9,'Ürün İş Listesi'!$P$30:$Z$50,8,0) -> 74 | E9: =VLOOKUP(C9,'Ürün İş Listesi'!$AQ$32:$AR$48,2,0) -> 37 | F9: =G9*D9 -> 65 | G9: =VLOOKUP(C9,'Ürün İş Listesi'!$P$30:$Z$50,11,0) -> 0.87837838 | J9: =IFERROR(VLOOKUP(C9,'Ürün İş Listesi'!$AQ$5:$AT$23,4,0),"") -> 2 | K9: =IFERROR(VLOOKUP(C9,'Ürün İş Listesi'!$AQ$5:$AR$23,2,0),"") -> 0 | L9: =IFERROR(M9*J9,"-") -> 1 | M9: =IFERROR(VLOOKUP(C9,'Ürün İş Listesi'!$P$5:$Z$23,11,0),"") -> 0.5
C10: KEP | D10: =VLOOKUP(C10,'Ürün İş Listesi'!$P$30:$Z$50,8,0) -> 48 | E10: =VLOOKUP(C10,'Ürün İş Listesi'!$AQ$32:$AR$48,2,0) -> 7 | F10: =G10*D10 -> 42 | G10: =VLOOKUP(C10,'Ürün İş Listesi'!$P$30:$Z$50,11,0) -> 0.875 | J10: =IFERROR(VLOOKUP(C10,'Ürün İş Listesi'!$AQ$5:$AT$23,4,0),"") -> 3 | K10: =IFERROR(VLOOKUP(C10,'Ürün İş Listesi'!$AQ$5:$AR$23,2,0),"") -> 0 | L10: =IFERROR(M10*J10,"-") -> 1 | M10: =IFERROR(VLOOKUP(C10,'Ürün İş Listesi'!$P$5:$Z$23,11,0),"") -> 0.33333333
C11: Kep Assist | D11: =VLOOKUP(C11,'Ürün İş Listesi'!$P$30:$Z$50,8,0) -> 49 | E11: =VLOOKUP(C11,'Ürün İş Listesi'!$AQ$32:$AR$48,2,0) -> 19 | F11: =G11*D11 -> 48 | G11: =VLOOKUP(C11,'Ürün İş Listesi'!$P$30:$Z$50,11,0) -> 0.97959184 | J11: =IFERROR(VLOOKUP(C11,'Ürün İş Listesi'!$AQ$5:$AT$23,4,0),"") -> 6 | K11: =IFERROR(VLOOKUP(C11,'Ürün İş Listesi'!$AQ$5:$AR$23,2,0),"") -> 1 | L11: =IFERROR(M11*J11,"-") -> 3 | M11: =IFERROR(VLOOKUP(C11,'Ürün İş Listesi'!$P$5:$Z$23,11,0),"") -> 0.5
C12: KEP İK BULUT | D12: =VLOOKUP(C12,'Ürün İş Listesi'!$P$30:$Z$50,8,0) -> 90 | E12: =VLOOKUP(C12,'Ürün İş Listesi'!$AQ$32:$AR$48,2,0) -> 33 | F12: =G12*D12 -> 82 | G12: =VLOOKUP(C12,'Ürün İş Listesi'!$P$30:$Z$50,11,0) -> 0.91111111 | J12: =IFERROR(VLOOKUP(C12,'Ürün İş Listesi'!$AQ$5:$AT$23,4,0),"") -> 6 | K12: =IFERROR(VLOOKUP(C12,'Ürün İş Listesi'!$AQ$5:$AR$23,2,0),"") -> 2 | L12: =IFERROR(M12*J12,"-") -> 2 | M12: =IFERROR(VLOOKUP(C12,'Ürün İş Listesi'!$P$5:$Z$23,11,0),"") -> 0.33333333
C13: Kep Web Servisi | D13: =VLOOKUP(C13,'Ürün İş Listesi'!$P$30:$Z$50,8,0) -> 6 | E13: =VLOOKUP(C13,'Ürün İş Listesi'!$AQ$32:$AR$48,2,0) -> 1 | F13: =G13*D13 -> 5 | G13: =VLOOKUP(C13,'Ürün İş Listesi'!$P$30:$Z$50,11,0) -> 0.83333333 | J13: =IFERROR(VLOOKUP(C13,'Ürün İş Listesi'!$AQ$5:$AT$23,4,0),"") | K13: =IFERROR(VLOOKUP(C13,'Ürün İş Listesi'!$AQ$5:$AR$23,2,0),"") | L13: =IFERROR(M13*J13,"-") -> - | M13: =IFERROR(VLOOKUP(C13,'Ürün İş Listesi'!$P$5:$Z$23,11,0),"")
C14: Mobil Uygulama | D14: =VLOOKUP(C14,'Ürün İş Listesi'!$P$30:$Z$50,8,0) -> 110 | E14: =VLOOKUP(C14,'Ürün İş Listesi'!$AQ$32:$AR$48,2,0) -> 65 | F14: =G14*D14 -> 97 | G14: =VLOOKUP(C14,'Ürün İş Listesi'!$P$30:$Z$50,11,0) -> 0.88181818 | J14: =IFERROR(VLOOKUP(C14,'Ürün İş Listesi'!$AQ$5:$AT$23,4,0),"") -> 5 | K14: =IFERROR(VLOOKUP(C14,'Ürün İş Listesi'!$AQ$5:$AR$23,2,0),"") -> 2 | L14: =IFERROR(M14*J14,"-") -> 5 | M14: =IFERROR(VLOOKUP(C14,'Ürün İş Listesi'!$P$5:$Z$23,11,0),"") -> 1
C15: Muhaberat Yönetim Sistemi | D15: =VLOOKUP(C15,'Ürün İş Listesi'!$P$30:$Z$50,8,0) -> 41 | E15: =VLOOKUP(C15,'Ürün İş Listesi'!$AQ$32:$AR$48,2,0) -> 17 | F15: =G15*D15 -> 41 | G15: =VLOOKUP(C15,'Ürün İş Listesi'!$P$30:$Z$50,11,0) -> 1 | J15: =IFERROR(VLOOKUP(C15,'Ürün İş Listesi'!$AQ$5:$AT$23,4,0),"") -> 2 | K15: =IFERROR(VLOOKUP(C15,'Ürün İş Listesi'!$AQ$5:$AR$23,2,0),"") -> 0 | L15: =IFERROR(M15*J15,"-") -> 1 | M15: =IFERROR(VLOOKUP(C15,'Ürün İş Listesi'!$P$5:$Z$23,11,0),"") -> 0.5
C16: TÜRKKEP İMZA | D16: =VLOOKUP(C16,'Ürün İş Listesi'!$P$30:$Z$50,8,0) -> 27 | E16: =VLOOKUP(C16,'Ürün İş Listesi'!$AQ$32:$AR$48,2,0) -> 10 | F16: =G16*D16 -> 25 | G16: =VLOOKUP(C16,'Ürün İş Listesi'!$P$30:$Z$50,11,0) -> 0.92592593 | J16: =IFERROR(VLOOKUP(C16,'Ürün İş Listesi'!$AQ$5:$AT$23,4,0),"") -> 1 | K16: =IFERROR(VLOOKUP(C16,'Ürün İş Listesi'!$AQ$5:$AR$23,2,0),"") -> 0 | L16: =IFERROR(M16*J16,"-") -> 0 | M16: =IFERROR(VLOOKUP(C16,'Ürün İş Listesi'!$P$5:$Z$23,11,0),"") -> 0
... C20: Yapay Zeka Destekli Çağrı Karşılama | D20: =VLOOKUP(C20,'Ürün İş Listesi'!$P$30:$Z$50,8,0) -> 11 | E20: =VLOOKUP(C20,'Ürün İş Listesi'!$AQ$32:$AR$48,2,0) -> 2 | F20: =G20*D20 -> 9 | G20: =VLOOKUP(C20,'Ürün İş Listesi'!$P$30:$Z$50,11,0) -> 0.81818182 | J20: =IFERROR(VLOOKUP(C20,'Ürün İş Listesi'!$AQ$5:$AT$23,4,0),"") | K20: =IFERROR(VLOOKUP(C20,'Ürün İş Listesi'!$AQ$5:$AR$23,2,0),"") | L20: =IFERROR(M20*J20,"-") -> - | M20: =IFERROR(VLOOKUP(C20,'Ürün İş Listesi'!$P$5:$Z$23,11,0),"")
C22: Genel Toplam | D22: =SUM(D5:D20) -> 862 | E22: =SUM(E5:E20) -> 269 | F22: =SUM(F5:F20) -> 770 | G22: =VLOOKUP(C22,'Ürün İş Listesi'!$P$30:$Z$50,11,0) -> 0.89425287 | J22: =SUM(J5:J19) -> 63 | K22: =SUM(K5:K19) -> 7 | L22: =SUM(L5:L19) -> 40 | M22: =L22/J22 -> 0.63492063 | N22: Bayram ve izin planlamaları dolayısıyla tamamlanma oranları düşük gerçekleşmiştir.

Sheet Ürün İş Listesi
A1: Issue Type | B1: Issue key | C1: Status | D1: Summary | E1: Project name | F1: x | G1: DEVAM EDEN SPRİNT | H1: GELECEK SPRİNT | I1: Durum | J1: Story Point2 | AQ1: DEVAM EDEN SPRİNT | AR1: Devam Eden Sprint
A2: Story | B2: CRM-281 | C2: To Do | D2: Türkkep -E-Güven CRM entegrasyonu Faz 2 | E2: CRM | F2: =VLOOKUP(B2,'Türkkep Jira'!B:F,5,0) -> #N/A | G2: =IF(IFERROR(VLOOKUP(B2,'Devam Eden Sprint'!B:B,1,0),"-")=B2,"Devam Eden Sprint","-") -> - | H2: =IF(IFERROR(VLOOKUP(B2,'Gelecek Sprint'!B:B,1,0),"-")=B2,"Gelecek Sprint","-") -> - | I2: =IFERROR(IF(AND(G2="Devam Eden Sprint",H2="Gelecek Sprint"),"Devam Eden ve Gelecek Sprint",IF(G2="Devam Eden Sprint","Devam Eden Sprint",IF(H2="Gelecek Sprint","Gelecek Sprint","Ürün İş Listesi"))),"Ürün İş Listesi") -> Ürün İş Listesi | P2: DEVAM EDEN SPRİNT | Q2: Devam Eden Sprint | AC2: DEVAM EDEN SPRİNT | AD2: Devam Eden Sprint | AQ2: Status | AR2: (Birden Çok Öğe)
A3: Story | B3: CRM-497 | C3: Done | D3: Saklama Kota Yükleme İşlemleri | E3: CRM | F3: =VLOOKUP(B3,'Türkkep Jira'!B:F,5,0) -> #N/A | G3: =IF(IFERROR(VLOOKUP(B3,'Devam Eden Sprint'!B:B,1,0),"-")=B3,"Devam Eden Sprint","-") -> - | H3: =IF(IFERROR(VLOOKUP(B3,'Gelecek Sprint'!B:B,1,0),"-")=B3,"Gelecek Sprint","-") -> - | I3: =IFERROR(IF(AND(G3="Devam Eden Sprint",H3="Gelecek Sprint"),"Devam Eden ve Gelecek Sprint",IF(G3="Devam Eden Sprint","Devam Eden Sprint",IF(H3="Gelecek Sprint","Gelecek Sprint","Ürün İş Listesi"))),"Ürün İş Listesi") -> Ürün İş Listesi
A4: Story | B4: CRM-533 | C4: Done | D4: KEP IK Mahremiyet & CRM Entegrasyonu | E4: CRM | F4: =VLOOKUP(B4,'Türkkep Jira'!B:F,5,0) -> #N/A | G4: =IF(IFERROR(VLOOKUP(B4,'Devam Eden Sprint'!B:B,1,0),"-")=B4,"Devam Eden Sprint","-") -> - | H4: =IF(IFERROR(VLOOKUP(B4,'Gelecek Sprint'!B:B,1,0),"-")=B4,"Gelecek Sprint","-") -> - | I4: =IFERROR(IF(AND(G4="Devam Eden Sprint",H4="Gelecek Sprint"),"Devam Eden ve Gelecek Sprint",IF(G4="Devam Eden Sprint","Devam Eden Sprint",IF(H4="Gelecek Sprint","Gelecek Sprint","Ürün İş Listesi"))),"Ürün İş Listesi") -> Ürün İş Listesi | P4: Say Durum | Q4: Sütun Etiketleri | AC4: Toplam Story Point2 | AD4: Sütun Etiketleri | AQ4: Say Durum | AR4: Sütun Etiketleri
A5: Story | B5: CRM-535 | C5: Done | D5: KEP IK Blulut NVİ Tamamlanan Çalışanların QR Kodlu Islak İmza Taahhütnamelerinin Üretilmesi | E5: CRM | F5: =VLOOKUP(B5,'Türkkep Jira'!B:F,5,0) -> #N/A | G5: =IF(IFERROR(VLOOKUP(B5,'Devam Eden Sprint'!B:B,1,0),"-")=B5,"Devam Eden Sprint","-") -> - | H5: =IF(IFERROR(VLOOKUP(B5,'Gelecek Sprint'!B:B,1,0),"-")=B5,"Gelecek Sprint","-") -> - | I5: =IFERROR(IF(AND(G5="Devam Eden Sprint",H5="Gelecek Sprint"),"Devam Eden ve Gelecek Sprint",IF(G5="Devam Eden Sprint","Devam Eden Sprint",IF(H5="Gelecek Sprint","Gelecek Sprint","Ürün İş Listesi"))),"Ürün İş Listesi") -> Ürün İş Listesi | P5: Satır Etiketleri | Q5: Done | R5: In Progress | S5: Publish | T5: To Do | U5: TO TEST | V5: In Test | W5: Genel Toplam | Y5: Sprint Perf. Oranı | AC5: Satır Etiketleri | AD5: Done | AE5: In Progress | AF5: In Test | AG5: Publish | AH5: To Do | AI5: TO TEST | AJ5: (boş) | AK5: Genel Toplam | AM5: Sprint Perf. Oranı | AQ5: Satır Etiketleri | AR5: Bug | AS5: Story | AT5: Genel Toplam
A6: Story | B6: CRM-541 | C6: Done | D6: Üretim Modülü için Tablo Modellenmesi | E6: CRM | F6: =VLOOKUP(B6,'Türkkep Jira'!B:F,5,0) -> #N/A | G6: =IF(IFERROR(VLOOKUP(B6,'Devam Eden Sprint'!B:B,1,0),"-")=B6,"Devam Eden Sprint","-") -> - | H6: =IF(IFERROR(VLOOKUP(B6,'Gelecek Sprint'!B:B,1,0),"-")=B6,"Gelecek Sprint","-") -> - | I6: =IFERROR(IF(AND(G6="Devam Eden Sprint",H6="Gelecek Sprint"),"Devam Eden ve Gelecek Sprint",IF(G6="Devam Eden Sprint","Devam Eden Sprint",IF(H6="Gelecek Sprint","Gelecek Sprint","Ürün İş Listesi"))),"Ürün İş Listesi") -> Ürün İş Listesi | P6: CRM | Q6: 5 | R6: 2 | T6: 2 | U6: 16 | V6: 2 | W6: 27 | Y6: =Q6/W6 -> 0.18518519 | Z6: =(Q6+SUM(U6:V6))/W6 -> 0.85185185 | AC6: CRM | AD6: 16 | AF6: 7 | AI6: 36 | AK6: 59 | AM6: =AD6/AK6 -> 0.27118644 | AQ6: CRM | AS6: 27 | AT6: 27
A7: Story | B7: CRM-542 | C7: Done | D7: Üretim Modülü için Anasayfa Filtre Ekranı | E7: CRM | F7: =VLOOKUP(B7,'Türkkep Jira'!B:F,5,0) -> #N/A | G7: =IF(IFERROR(VLOOKUP(B7,'Devam Eden Sprint'!B:B,1,0),"-")=B7,"Devam Eden Sprint","-") -> - | H7: =IF(IFERROR(VLOOKUP(B7,'Gelecek Sprint'!B:B,1,0),"-")=B7,"Gelecek Sprint","-") -> - | I7: =IFERROR(IF(AND(G7="Devam Eden Sprint",H7="Gelecek Sprint"),"Devam Eden ve Gelecek Sprint",IF(G7="Devam Eden Sprint","Devam Eden Sprint",IF(H7="Gelecek Sprint","Gelecek Sprint","Ürün İş Listesi"))),"Ürün İş Listesi") -> Ürün İş Listesi | J7: 3 | P7: E-Defter | Q7: 1 | R7: 1 | T7: 2 | U7: 1 | W7: 5 | Y7: =Q7/W7 -> 0.2 | Z7: =(Q7+SUM(U7:V7))/W7 -> 0.4 | AC7: E-Defter | AH7: 6 | AI7: 3 | AK7: 9 | AM7: =AD7/AK7 -> 0 | AQ7: Destek Portal | AS7: 1 | AT7: 1
A8: Story | B8: CRM-543 | C8: Done | D8: Üretim Modülü Liste Sayfasının Geliştirmesi | E8: CRM | F8: =VLOOKUP(B8,'Türkkep Jira'!B:F,5,0) -> #N/A | G8: =IF(IFERROR(VLOOKUP(B8,'Devam Eden Sprint'!B:B,1,0),"-")=B8,"Devam Eden Sprint","-") -> - | H8: =IF(IFERROR(VLOOKUP(B8,'Gelecek Sprint'!B:B,1,0),"-")=B8,"Gelecek Sprint","-") -> - | I8: =IFERROR(IF(AND(G8="Devam Eden Sprint",H8="Gelecek Sprint"),"Devam Eden ve Gelecek Sprint",IF(G8="Devam Eden Sprint","Devam Eden Sprint",IF(H8="Gelecek Sprint","Gelecek Sprint","Ürün İş Listesi"))),"Ürün İş Listesi") -> Ürün İş Listesi | J8: 5 | P8: E-Fatura | Q8: 1 | R8: 3 | U8: 1 | W8: 5 | Y8: =Q8/W8 -> 0.2 | Z8: =(Q8+SUM(U8:V8))/W8 -> 0.4 | AC8: E-Fatura | AM8: =AD8/AK8 -> #DIV/0! | AQ8: E-Defter | AR8: 1 | AS8: 4 | AT8: 5
A9: Story | B9: CRM-544 | C9: Done | D9: Üretim Modülü Mütabakat Sürecinin Geliştirmesi | E9: CRM | F9: =VLOOKUP(B9,'Türkkep Jira'!B:F,5,0) -> #N/A | G9: =IF(IFERROR(VLOOKUP(B9,'Devam Eden Sprint'!B:B,1,0),"-")=B9,"Devam Eden Sprint","-") -> - | H9: =IF(IFERROR(VLOOKUP(B9,'Gelecek Sprint'!B:B,1,0),"-")=B9,"Gelecek Sprint","-") -> - | I9: =IFERROR(IF(AND(G9="Devam Eden Sprint",H9="Gelecek Sprint"),"Devam Eden ve Gelecek Sprint",IF(G9="Devam Eden Sprint","Devam Eden Sprint",IF(H9="Gelecek Sprint","Gelecek Sprint","Ürün İş Listesi"))),"Ürün İş Listesi") -> Ürün İş Listesi | P9: Entegrasyon Suit | T9: 1 | U9: 1 | W9: 2 | Y9: =Q9/W9 -> 0 | Z9: =(Q9+SUM(U9:V9))/W9 -> 0.5 | AC9: Entegrasyon Suit | AI9: 2 | AK9: 2 | AM9: =AD9/AK9 -> 0 | AQ9: E-Fatura | AR9: 1 | AS9: 4 | AT9: 5
A10: Story | B10: CRM-545 | C10: Done | D10: KEP IK Bulut NVİ Tamamlanmayan Çalışanların QR Kodlu Islak İmza Taahhütnamelerinin Üretilmesi için Servis Geliştirmesi | E10: CRM | F10: =VLOOKUP(B10,'Türkkep Jira'!B:F,5,0) -> #N/A | G10: =IF(IFERROR(VLOOKUP(B10,'Devam Eden Sprint'!B:B,1,0),"-")=B10,"Devam Eden Sprint","-") -> - | H10: =IF(IFERROR(VLOOKUP(B10,'Gelecek Sprint'!B:B,1,0),"-")=B10,"Gelecek Sprint","-") -> - | I10: =IFERROR(IF(AND(G10="Devam Eden Sprint",H10="Gelecek Sprint"),"Devam Eden ve Gelecek Sprint",IF(G10="Devam Eden Sprint","Devam Eden Sprint",IF(H10="Gelecek Sprint","Gelecek Sprint","Ürün İş Listesi"))),"Ürün İş Listesi") -> Ürün İş Listesi | P10: KEP | Q10: 1 | R10: 2 | W10: 3 | Y10: =Q10/W10 -> 0.33333333 | Z10: =(Q10+SUM(U10:V10))/W10 -> 0.33333333 | AC10: KEP | AD10: 3 | AE10: 8 | AK10: 11 | AM10: =AD10/AK10 -> 0.27272727 | AQ10: Entegrasyon Suit | AS10: 2 | AT10: 2
A11: Story | B11: CRM-546 | C11: Done | D11: KEP IK Bulut Çalışanların QR Kodlu Islak İmza Taahhütnamelerinin Uygulama İçerisinden Toplu İndirilmesi | E11: CRM | F11: =VLOOKUP(B11,'Türkkep Jira'!B:F,5,0) -> #N/A | G11: =IF(IFERROR(VLOOKUP(B11,'Devam Eden Sprint'!B:B,1,0),"-")=B11,"Devam Eden Sprint","-") -> - | H11: =IF(IFERROR(VLOOKUP(B11,'Gelecek Sprint'!B:B,1,0),"-")=B11,"Gelecek Sprint","-") -> - | I11: =IFERROR(IF(AND(G11="Devam Eden Sprint",H11="Gelecek Sprint"),"Devam Eden ve Gelecek Sprint",IF(G11="Devam Eden Sprint","Devam Eden Sprint",IF(H11="Gelecek Sprint","Gelecek Sprint","Ürün İş Listesi"))),"Ürün İş Listesi") -> Ürün İş Listesi | P11: Kep Assist | Q11: 3 | R11: 2 | T11: 1 | W11: 6 | Y11: =Q11/W11 -> 0.5 | Z11: =(Q11+SUM(U11:V11))/W11 -> 0.5 | AC11: Kep Assist | AD11: 5 | AE11: 3 | AK11: 8 | AM11: =AD11/AK11 -> 0.625 | AQ11: KEP | AS11: 3 | AT11: 3
A12: Story | B12: CRM-550 | C12: Done | D12: Multikep Müşteri Bilgilerinin CRM Sözleşmeden Aktarılması | E12: CRM | F12: =VLOOKUP(B12,'Türkkep Jira'!B:F,5,0) -> #N/A | G12: =IF(IFERROR(VLOOKUP(B12,'Devam Eden Sprint'!B:B,1,0),"-")=B12,"Devam Eden Sprint","-") -> - | H12: =IF(IFERROR(VLOOKUP(B12,'Gelecek Sprint'!B:B,1,0),"-")=B12,"Gelecek Sprint","-") -> - | I12: =IFERROR(IF(AND(G12="Devam Eden Sprint",H12="Gelecek Sprint"),"Devam Eden ve Gelecek Sprint",IF(G12="Devam Eden Sprint","Devam Eden Sprint",IF(H12="Gelecek Sprint","Gelecek Sprint","Ürün İş Listesi"))),"Ürün İş Listesi") -> Ürün İş Listesi | P12: KEP İK BULUT | R12: 1 | S12: 1 | T12: 2 | U12: 2 | W12: 6 | Y12: =Q12/W12 -> 0 | Z12: =(Q12+SUM(U12:V12))/W12 -> 0.33333333 | AC12: KEP İK BULUT | AE12: 3 | AG12: 2 | AH12: 2 | AI12: 6 | AJ12: 3 | AK12: 16 | AM12: =AD12/AK12 -> 0 | AQ12: Kep Assist | AR12: 1 | AS12: 5 | AT12: 6
A13: Story | B13: CRM-551 | C13: Done | D13: Multikep Modüllerinin CRM İşlem Kaydından Aktif Edilmesi | E13: CRM | F13: =VLOOKUP(B13,'Türkkep Jira'!B:F,5,0) -> #N/A | G13: =IF(IFERROR(VLOOKUP(B13,'Devam Eden Sprint'!B:B,1,0),"-")=B13,"Devam Eden Sprint","-") -> - | H13: =IF(IFERROR(VLOOKUP(B13,'Gelecek Sprint'!B:B,1,0),"-")=B13,"Gelecek Sprint","-") -> - | I13: =IFERROR(IF(AND(G13="Devam Eden Sprint",H13="Gelecek Sprint"),"Devam Eden ve Gelecek Sprint",IF(G13="Devam Eden Sprint","Devam Eden Sprint",IF(H13="Gelecek Sprint","Gelecek Sprint","Ürün İş Listesi"))),"Ürün İş Listesi") -> Ürün İş Listesi | P13: Mobil Uygulama | Q13: 5 | W13: 5 | Y13: =Q13/W13 -> 1 | Z13: =(Q13+SUM(U13:V13))/W13 -> 1 | AC13: Mobil Uygulama | AD13: 11 | AK13: 11 | AM13: =AD13/AK13 -> 1 | AQ13: KEP İK BULUT | AR13: 2 | AS13: 4 | AT13: 6
A14: Story | B14: CRM-553 | C14: Done | D14: Multikep Aktarılan Kullanıcılarının Update Edilmesi | E14: CRM | F14: =VLOOKUP(B14,'Türkkep Jira'!B:F,5,0) -> #N/A | G14: =IF(IFERROR(VLOOKUP(B14,'Devam Eden Sprint'!B:B,1,0),"-")=B14,"Devam Eden Sprint","-") -> - | H14: =IF(IFERROR(VLOOKUP(B14,'Gelecek Sprint'!B:B,1,0),"-")=B14,"Gelecek Sprint","-") -> - | I14: =IFERROR(IF(AND(G14="Devam Eden Sprint",H14="Gelecek Sprint"),"Devam Eden ve Gelecek Sprint",IF(G14="Devam Eden Sprint","Devam Eden Sprint",IF(H14="Gelecek Sprint","Gelecek Sprint","Ürün İş Listesi"))),"Ürün İş Listesi") -> Ürün İş Listesi | P14: Muhaberat Yönetim Sistemi | Q14: 1 | T14: 1 | W14: 2 | Y14: =Q14/W14 -> 0.5 | Z14: =(Q14+SUM(U14:V14))/W14 -> 0.5 | AC14: Muhaberat Yönetim Sistemi | AD14: 3 | AH14: 8 | AK14: 11 | AM14: =AD14/AK14 -> 0.27272727 | AQ14: Mobil Uygulama | AR14: 2 | AS14: 3 | AT14: 5
A15: Story | B15: CRM-554 | C15: Done | D15: CRM Kurumsal Müşteri Oluşturma MERSİS Entegrasyonu | E15: CRM | F15: =VLOOKUP(B15,'Türkkep Jira'!B:F,5,0) -> #N/A | G15: =IF(IFERROR(VLOOKUP(B15,'Devam Eden Sprint'!B:B,1,0),"-")=B15,"Devam Eden Sprint","-") -> - | H15: =IF(IFERROR(VLOOKUP(B15,'Gelecek Sprint'!B:B,1,0),"-")=B15,"Gelecek Sprint","-") -> - | I15: =IFERROR(IF(AND(G15="Devam Eden Sprint",H15="Gelecek Sprint"),"Devam Eden ve Gelecek Sprint",IF(G15="Devam Eden Sprint","Devam Eden Sprint",IF(H15="Gelecek Sprint","Gelecek Sprint","Ürün İş Listesi"))),"Ürün İş Listesi") -> Ürün İş Listesi | J15: 5 | P15: TÜRKKEP İMZA | T15: 1 | W15: 1 | Y15: =Q15/W15 -> 0 | Z15: =(Q15+SUM(U15:V15))/W15 -> 0 | AC15: MULTİKEP | AM15: =AD15/AK15 -> #DIV/0! | AQ15: Muhaberat Yönetim Sistemi | AS15: 2 | AT15: 2
A16: Story | B16: CRM-555 | C16: Done | D16: KEP IK Toplu Açılış için CRM den Çalışan Listesini Insert Etme | E16: CRM | F16: =VLOOKUP(B16,'Türkkep Jira'!B:F,5,0) -> #N/A | G16: =IF(IFERROR(VLOOKUP(B16,'Devam Eden Sprint'!B:B,1,0),"-")=B16,"Devam Eden Sprint","-") -> - | H16: =IF(IFERROR(VLOOKUP(B16,'Gelecek Sprint'!B:B,1,0),"-")=B16,"Gelecek Sprint","-") -> - | I16: =IFERROR(IF(AND(G16="Devam Eden Sprint",H16="Gelecek Sprint"),"Devam Eden ve Gelecek Sprint",IF(G16="Devam Eden Sprint","Devam Eden Sprint",IF(H16="Gelecek Sprint","Gelecek Sprint","Ürün İş Listesi"))),"Ürün İş Listesi") -> Ürün İş Listesi | P16: UKDS | Q16: 4 | W16: 4 | Y16: =Q16/W16 -> 1 | Z16: =(Q16+SUM(U16:V16))/W16 -> 1 | AC16: TÜRKKEP İMZA | AM16: =AD16/AK16 -> #DIV/0! | AQ16: TÜRKKEP İMZA | AS16: 1 | AT16: 1
A17: Story | B17: CRM-558 | C17: Done | D17: KEP IK Kullanıcı için İşlem Yetkilisi Değişiklikleri | E17: CRM | F17: =VLOOKUP(B17,'Türkkep Jira'!B:F,5,0) -> #N/A | G17: =IF(IFERROR(VLOOKUP(B17,'Devam Eden Sprint'!B:B,1,0),"-")=B17,"Devam Eden Sprint","-") -> - | H17: =IF(IFERROR(VLOOKUP(B17,'Gelecek Sprint'!B:B,1,0),"-")=B17,"Gelecek Sprint","-") -> - | I17: =IFERROR(IF(AND(G17="Devam Eden Sprint",H17="Gelecek Sprint"),"Devam Eden ve Gelecek Sprint",IF(G17="Devam Eden Sprint","Devam Eden Sprint",IF(H17="Gelecek Sprint","Gelecek Sprint","Ürün İş Listesi"))),"Ürün İş Listesi") -> Ürün İş Listesi | P17: Genel Toplam | Q17: 21 | R17: 11 | S17: 1 | T17: 10 | U17: 21 | V17: 2 | W17: 66 | Y17: =Q17/W17 -> 0.31818182 | Z17: =(Q17+SUM(U17:V17))/W17 -> 0.66666667 | AC17: Genel Toplam | AD17: 38 | AE17: 14 | AF17: 7 | AG17: 2 | AH17: 16 | AI17: 47 | AJ17: 3 | AK17: 127 | AM17: =AD17/AK17 -> 0.2992126 | AQ17: Genel Toplam | AR17: 7 | AS17: 56 | AT17: 63
A18: Story | B18: CRM-559 | C18: Done | D18: e-İmza UKDS Bilgilendirme Hk. | E18: CRM | F18: =VLOOKUP(B18,'Türkkep Jira'!B:F,5,0) -> #N/A | G18: =IF(IFERROR(VLOOKUP(B18,'Devam Eden Sprint'!B:B,1,0),"-")=B18,"Devam Eden Sprint","-") -> - | H18: =IF(IFERROR(VLOOKUP(B18,'Gelecek Sprint'!B:B,1,0),"-")=B18,"Gelecek Sprint","-") -> - | I18: =IFERROR(IF(AND(G18="Devam Eden Sprint",H18="Gelecek Sprint"),"Devam Eden ve Gelecek Sprint",IF(G18="Devam Eden Sprint","Devam Eden Sprint",IF(H18="Gelecek Sprint","Gelecek Sprint","Ürün İş Listesi"))),"Ürün İş Listesi") -> Ürün İş Listesi | Y18: =Q18/W18 -> #DIV/0! | Z18: =(Q18+SUM(U18:V18))/W18 -> #DIV/0! | AM18: =AD18/AK18 -> #DIV/0!
A19: Story | B19: CRM-560 | C19: Done | D19: MultiKEP Ek Kullanıcı Aktarılması | E19: CRM | F19: =VLOOKUP(B19,'Türkkep Jira'!B:F,5,0) -> #N/A | G19: =IF(IFERROR(VLOOKUP(B19,'Devam Eden Sprint'!B:B,1,0),"-")=B19,"Devam Eden Sprint","-") -> - | H19: =IF(IFERROR(VLOOKUP(B19,'Gelecek Sprint'!B:B,1,0),"-")=B19,"Gelecek Sprint","-") -> - | I19: =IFERROR(IF(AND(G19="Devam Eden Sprint",H19="Gelecek Sprint"),"Devam Eden ve Gelecek Sprint",IF(G19="Devam Eden Sprint","Devam Eden Sprint",IF(H19="Gelecek Sprint","Gelecek Sprint","Ürün İş Listesi"))),"Ürün İş Listesi") -> Ürün İş Listesi | Y19: =Q19/W19 -> #DIV/0! | Z19: =(Q19+SUM(U19:V19))/W19 -> #DIV/0!
A20: Story | B20: CRM-562 | C20: Done | D20: Yenileme Hatırlatma Maili Akışına Pasif Kullanıcı Kuralının Eklenmesi | E20: CRM | F20: =VLOOKUP(B20,'Türkkep Jira'!B:F,5,0) -> #N/A | G20: =IF(IFERROR(VLOOKUP(B20,'Devam Eden Sprint'!B:B,1,0),"-")=B20,"Devam Eden Sprint","-") -> - | H20: =IF(IFERROR(VLOOKUP(B20,'Gelecek Sprint'!B:B,1,0),"-")=B20,"Gelecek Sprint","-") -> - | I20: =IFERROR(IF(AND(G20="Devam Eden Sprint",H20="Gelecek Sprint"),"Devam Eden ve Gelecek Sprint",IF(G20="Devam Eden Sprint","Devam Eden Sprint",IF(H20="Gelecek Sprint","Gelecek Sprint","Ürün İş Listesi"))),"Ürün İş Listesi") -> Ürün İş Listesi | J20: 3 | Y20: =Q20/W20 -> #DIV/0! | Z20: =(Q20+SUM(U20:V20))/W20 -> #DIV/0!
A21: Story | B21: CRM-565 | C21: Done | D21: Toplu Teklif Oluşturma İşlemi | E21: CRM | F21: =VLOOKUP(B21,'Türkkep Jira'!B:F,5,0) -> #N/A | G21: =IF(IFERROR(VLOOKUP(B21,'Devam Eden Sprint'!B:B,1,0),"-")=B21,"Devam Eden Sprint","-") -> - | H21: =IF(IFERROR(VLOOKUP(B21,'Gelecek Sprint'!B:B,1,0),"-")=B21,"Gelecek Sprint","-") -> - | I21: =IFERROR(IF(AND(G21="Devam Eden Sprint",H21="Gelecek Sprint"),"Devam Eden ve Gelecek Sprint",IF(G21="Devam Eden Sprint","Devam Eden Sprint",IF(H21="Gelecek Sprint","Gelecek Sprint","Ürün İş Listesi"))),"Ürün İş Listesi") -> Ürün İş Listesi | Y21: =Q21/W21 -> #DIV/0! | Z21: =(Q21+SUM(U21:V21))/W21 -> #DIV/0!
A22: Story | B22: CRM-568 | C22: Done | D22: MERSİS Ek Geliştirme | E22: CRM | F22: =VLOOKUP(B22,'Türkkep Jira'!B:F,5,0) -> #N/A | G22: =IF(IFERROR(VLOOKUP(B22,'Devam Eden Sprint'!B:B,1,0),"-")=B22,"Devam Eden Sprint","-") -> - | H22: =IF(IFERROR(VLOOKUP(B22,'Gelecek Sprint'!B:B,1,0),"-")=B22,"Gelecek Sprint","-") -> - | I22: =IFERROR(IF(AND(G22="Devam Eden Sprint",H22="Gelecek Sprint"),"Devam Eden ve Gelecek Sprint",IF(G22="Devam Eden Sprint","Devam Eden Sprint",IF(H22="Gelecek Sprint","Gelecek Sprint","Ürün İş Listesi"))),"Ürün İş Listesi") -> Ürün İş Listesi | J22: 3 | Y22: =Q22/W22 -> #DIV/0! | Z22: =(Q22+SUM(U22:V22))/W22 -> #DIV/0!
A23: Story | B23: CRM-569 | C23: Done | D23: Satış Rapor Yeni Müşteri Statüsü | E23: CRM | F23: =VLOOKUP(B23,'Türkkep Jira'!B:F,5,0) -> #N/A | G23: =IF(IFERROR(VLOOKUP(B23,'Devam Eden Sprint'!B:B,1,0),"-")=B23,"Devam Eden Sprint","-") -> - | H23: =IF(IFERROR(VLOOKUP(B23,'Gelecek Sprint'!B:B,1,0),"-")=B23,"Gelecek Sprint","-") -> - | I23: =IFERROR(IF(AND(G23="Devam Eden Sprint",H23="Gelecek Sprint"),"Devam Eden ve Gelecek Sprint",IF(G23="Devam Eden Sprint","Devam Eden Sprint",IF(H23="Gelecek Sprint","Gelecek Sprint","Ürün İş Listesi"))),"Ürün İş Listesi") -> Ürün İş Listesi | J23: 2
A24: Bug | B24: CRM-570 | C24: Done | D24: Duplicate Teklif Numarası Hatası | E24: CRM | F24: =VLOOKUP(B24,'Türkkep Jira'!B:F,5,0) -> #N/A | G24: =IF(IFERROR(VLOOKUP(B24,'Devam Eden Sprint'!B:B,1,0),"-")=B24,"Devam Eden Sprint","-") -> - | H24: =IF(IFERROR(VLOOKUP(B24,'Gelecek Sprint'!B:B,1,0),"-")=B24,"Gelecek Sprint","-") -> - | I24: =IFERROR(IF(AND(G24="Devam Eden Sprint",H24="Gelecek Sprint"),"Devam Eden ve Gelecek Sprint",IF(G24="Devam Eden Sprint","Devam Eden Sprint",IF(H24="Gelecek Sprint","Gelecek Sprint","Ürün İş Listesi"))),"Ürün İş Listesi") -> Ürün İş Listesi | J24: 3
A25: Bug | B25: CRM-571 | C25: Done | D25: İş Bankası Sanal POS Api User Değişikliği | E25: CRM | F25: =VLOOKUP(B25,'Türkkep Jira'!B:F,5,0) -> #N/A | G25: =IF(IFERROR(VLOOKUP(B25,'Devam Eden Sprint'!B:B,1,0),"-")=B25,"Devam Eden Sprint","-") -> - | H25: =IF(IFERROR(VLOOKUP(B25,'Gelecek Sprint'!B:B,1,0),"-")=B25,"Gelecek Sprint","-") -> - | I25: =IFERROR(IF(AND(G25="Devam Eden Sprint",H25="Gelecek Sprint"),"Devam Eden ve Gelecek Sprint",IF(G25="Devam Eden Sprint","Devam Eden Sprint",IF(H25="Gelecek Sprint","Gelecek Sprint","Ürün İş Listesi"))),"Ürün İş Listesi") -> Ürün İş Listesi | J25: 1
A26: Bug | B26: CRM-572 | C26: Done | D26: Pazarama Bundle Hatası | E26: CRM | F26: =VLOOKUP(B26,'Türkkep Jira'!B:F,5,0) -> #N/A | G26: =IF(IFERROR(VLOOKUP(B26,'Devam Eden Sprint'!B:B,1,0),"-")=B26,"Devam Eden Sprint","-") -> - | H26: =IF(IFERROR(VLOOKUP(B26,'Gelecek Sprint'!B:B,1,0),"-")=B26,"Gelecek Sprint","-") -> - | I26: =IFERROR(IF(AND(G26="Devam Eden Sprint",H26="Gelecek Sprint"),"Devam Eden ve Gelecek Sprint",IF(G26="Devam Eden Sprint","Devam Eden Sprint",IF(H26="Gelecek Sprint","Gelecek Sprint","Ürün İş Listesi"))),"Ürün İş Listesi") -> Ürün İş Listesi | J26: 3
A27: Story | B27: CRM-573 | C27: Done | D27: Müşteri Modülünde Mail Adresi İle Müşteri Listeleme | E27: CRM | F27: =VLOOKUP(B27,'Türkkep Jira'!B:F,5,0) -> #N/A | G27: =IF(IFERROR(VLOOKUP(B27,'Devam Eden Sprint'!B:B,1,0),"-")=B27,"Devam Eden Sprint","-") -> - | H27: =IF(IFERROR(VLOOKUP(B27,'Gelecek Sprint'!B:B,1,0),"-")=B27,"Gelecek Sprint","-") -> - | I27: =IFERROR(IF(AND(G27="Devam Eden Sprint",H27="Gelecek Sprint"),"Devam Eden ve Gelecek Sprint",IF(G27="Devam Eden Sprint","Devam Eden Sprint",IF(H27="Gelecek Sprint","Gelecek Sprint","Ürün İş Listesi"))),"Ürün İş Listesi") -> Ürün İş Listesi | J27: 3 | P27: DEVAM EDEN SPRİNT | Q27: (Tümü) | AC27: Tüm Ürün İş Listesi
A28: Story | B28: CRM-574 | C28: Done | D28: Güvenlik Grubu Değişiklik Tarihçesi Hk. | E28: CRM | F28: =VLOOKUP(B28,'Türkkep Jira'!B:F,5,0) -> #N/A | G28: =IF(IFERROR(VLOOKUP(B28,'Devam Eden Sprint'!B:B,1,0),"-")=B28,"Devam Eden Sprint","-") -> - | H28: =IF(IFERROR(VLOOKUP(B28,'Gelecek Sprint'!B:B,1,0),"-")=B28,"Gelecek Sprint","-") -> - | I28: =IFERROR(IF(AND(G28="Devam Eden Sprint",H28="Gelecek Sprint"),"Devam Eden ve Gelecek Sprint",IF(G28="Devam Eden Sprint","Devam Eden Sprint",IF(H28="Gelecek Sprint","Gelecek Sprint","Ürün İş Listesi"))),"Ürün İş Listesi") -> Ürün İş Listesi | J28: 3 | AC28: Status | AD28: (Birden Çok Öğe)
A29: Story | B29: CRM-577 | C29: Done | D29: Dijikolay Potansiyel Müşteri Entegrasyonu Hk. | E29: CRM | F29: =VLOOKUP(B29,'Türkkep Jira'!B:F,5,0) -> #N/A | G29: =IF(IFERROR(VLOOKUP(B29,'Devam Eden Sprint'!B:B,1,0),"-")=B29,"Devam Eden Sprint","-") -> - | H29: =IF(IFERROR(VLOOKUP(B29,'Gelecek Sprint'!B:B,1,0),"-")=B29,"Gelecek Sprint","-") -> - | I29: =IFERROR(IF(AND(G29="Devam Eden Sprint",H29="Gelecek Sprint"),"Devam Eden ve Gelecek Sprint",IF(G29="Devam Eden Sprint","Devam Eden Sprint",IF(H29="Gelecek Sprint","Gelecek Sprint","Ürün İş Listesi"))),"Ürün İş Listesi") -> Ürün İş Listesi | J29: 1 | P29: Say Durum | Q29: Sütun Etiketleri
A30: Story | B30: CRM-580 | C30: Done | D30: KEP IK Toplu Açılış için CRM den Çalışan Listesini Insert Etme Ek Geliştirme | E30: CRM | F30: =VLOOKUP(B30,'Türkkep Jira'!B:F,5,0) -> #N/A | G30: =IF(IFERROR(VLOOKUP(B30,'Devam Eden Sprint'!B:B,1,0),"-")=B30,"Devam Eden Sprint","-") -> - | H30: =IF(IFERROR(VLOOKUP(B30,'Gelecek Sprint'!B:B,1,0),"-")=B30,"Gelecek Sprint","-") -> - | I30: =IFERROR(IF(AND(G30="Devam Eden Sprint",H30="Gelecek Sprint"),"Devam Eden ve Gelecek Sprint",IF(G30="Devam Eden Sprint","Devam Eden Sprint",IF(H30="Gelecek Sprint","Gelecek Sprint","Ürün İş Listesi"))),"Ürün İş Listesi") -> Ürün İş Listesi | J30: 8 | P30: Satır Etiketleri | Q30: Done | R30: In Progress | S30: In Test | T30: To Do | U30: TO TEST | V30: Publish | W30: Genel Toplam | AC30: Say Durum | AD30: Sütun Etiketleri | AJ30: İş Adedi | AQ30: Say Durum | AR30: Sütun Etiketleri
A31: Story | B31: CRM-581 | C31: Done | D31: Toplu IK Excel Yüklemede Hatalı Excelin Export Edilmesi | E31: CRM | F31: =VLOOKUP(B31,'Türkkep Jira'!B:F,5,0) -> #N/A | G31: =IF(IFERROR(VLOOKUP(B31,'Devam Eden Sprint'!B:B,1,0),"-")=B31,"Devam Eden Sprint","-") -> - | H31: =IF(IFERROR(VLOOKUP(B31,'Gelecek Sprint'!B:B,1,0),"-")=B31,"Gelecek Sprint","-") -> - | I31: =IFERROR(IF(AND(G31="Devam Eden Sprint",H31="Gelecek Sprint"),"Devam Eden ve Gelecek Sprint",IF(G31="Devam Eden Sprint","Devam Eden Sprint",IF(H31="Gelecek Sprint","Gelecek Sprint","Ürün İş Listesi"))),"Ürün İş Listesi") -> Ürün İş Listesi | J31: 3 | P31: CRM | Q31: 128 | S31: 5 | T31: 14 | U31: 5 | W31: 152 | Z31: =Q31/W31 -> 0.84210526 | AC31: Satır Etiketleri | AD31: Ürün İş Listesi | AE31: Devam Eden Sprint | AF31: Devam Eden ve Gelecek Sprint | AG31: Gelecek Sprint | AH31: Genel Toplam | AJ31: Tamamlanan Sprint | AK31: Gelecek Sprint | AQ31: Satır Etiketleri | AR31: Bug | AS31: Story | AT31: Sub-task | AU31: Task | AV31: Genel Toplam
A32: Bug | B32: CRM-582 | C32: Done | D32: Toplu KEP IK Açılış Excelinde Güvenlik Kelimesi | E32: CRM | F32: =VLOOKUP(B32,'Türkkep Jira'!B:F,5,0) -> #N/A | G32: =IF(IFERROR(VLOOKUP(B32,'Devam Eden Sprint'!B:B,1,0),"-")=B32,"Devam Eden Sprint","-") -> - | H32: =IF(IFERROR(VLOOKUP(B32,'Gelecek Sprint'!B:B,1,0),"-")=B32,"Gelecek Sprint","-") -> - | I32: =IFERROR(IF(AND(G32="Devam Eden Sprint",H32="Gelecek Sprint"),"Devam Eden ve Gelecek Sprint",IF(G32="Devam Eden Sprint","Devam Eden Sprint",IF(H32="Gelecek Sprint","Gelecek Sprint","Ürün İş Listesi"))),"Ürün İş Listesi") -> Ürün İş Listesi | J32: 2 | P32: Destek Portal | Q32: 26 | T32: 3 | W32: 29 | Z32: =Q32/W32 -> 0.89655172 | AC32: CRM | AD32: 177 | AE32: 5 | AF32: 22 | AG32: 2 | AH32: 206 | AJ32: =SUM(AD32:AE32) -> 182 | AK32: =ROUNDUP(SUM(AE32:AF32),0) -> 27 | AQ32: CRM | AR32: 10 | AS32: 196 | AV32: 206
A33: Story | B33: CRM-583 | C33: Done | D33: Toplu KEP IK Açılışlarında Bildirim Gönderilmesi | E33: CRM | F33: =VLOOKUP(B33,'Türkkep Jira'!B:F,5,0) -> #N/A | G33: =IF(IFERROR(VLOOKUP(B33,'Devam Eden Sprint'!B:B,1,0),"-")=B33,"Devam Eden Sprint","-") -> - | H33: =IF(IFERROR(VLOOKUP(B33,'Gelecek Sprint'!B:B,1,0),"-")=B33,"Gelecek Sprint","-") -> - | I33: =IFERROR(IF(AND(G33="Devam Eden Sprint",H33="Gelecek Sprint"),"Devam Eden ve Gelecek Sprint",IF(G33="Devam Eden Sprint","Devam Eden Sprint",IF(H33="Gelecek Sprint","Gelecek Sprint","Ürün İş Listesi"))),"Ürün İş Listesi") -> Ürün İş Listesi | J33: 3 | P33: E-Defter | Q33: 26 | W33: 26 | Z33: =Q33/W33 -> 1 | AC33: Destek Portal | AD33: 30 | AH33: 30 | AJ33: =SUM(AD33:AE33) -> 30 | AK33: =ROUNDUP(SUM(AE33:AF33),0) -> 0 | AQ33: Destek Portal | AR33: 11 | AS33: 20 | AV33: 31
A34: Story | B34: CRM-584 | C34: Done | D34: KEP Adresi ile Arama | E34: CRM | F34: =VLOOKUP(B34,'Türkkep Jira'!B:F,5,0) -> #N/A | G34: =IF(IFERROR(VLOOKUP(B34,'Devam Eden Sprint'!B:B,1,0),"-")=B34,"Devam Eden Sprint","-") -> - | H34: =IF(IFERROR(VLOOKUP(B34,'Gelecek Sprint'!B:B,1,0),"-")=B34,"Gelecek Sprint","-") -> - | I34: =IFERROR(IF(AND(G34="Devam Eden Sprint",H34="Gelecek Sprint"),"Devam Eden ve Gelecek Sprint",IF(G34="Devam Eden Sprint","Devam Eden Sprint",IF(H34="Gelecek Sprint","Gelecek Sprint","Ürün İş Listesi"))),"Ürün İş Listesi") -> Ürün İş Listesi | J34: 3 | P34: E-Fatura | Q34: 108 | T34: 19 | W34: 127 | Z34: =Q34/W34 -> 0.8503937 | AC34: E-Defter | AD34: 37 | AE34: 2 | AF34: 3 | AG34: 3 | AH34: 45 | AJ34: =SUM(AD34:AE34) -> 39 | AK34: =ROUNDUP(SUM(AE34:AF34),0) -> 5 | AQ34: E-Defter | AR34: 12 | AS34: 35 | AV34: 47
A35: Story | B35: CRM-587 | C35: To Do | D35: e-İmza Başvuruları için Dış Servis Yazılması | E35: CRM | F35: =VLOOKUP(B35,'Türkkep Jira'!B:F,5,0) -> #N/A | G35: =IF(IFERROR(VLOOKUP(B35,'Devam Eden Sprint'!B:B,1,0),"-")=B35,"Devam Eden Sprint","-") -> - | H35: =IF(IFERROR(VLOOKUP(B35,'Gelecek Sprint'!B:B,1,0),"-")=B35,"Gelecek Sprint","-") -> - | I35: =IFERROR(IF(AND(G35="Devam Eden Sprint",H35="Gelecek Sprint"),"Devam Eden ve Gelecek Sprint",IF(G35="Devam Eden Sprint","Devam Eden Sprint",IF(H35="Gelecek Sprint","Gelecek Sprint","Ürün İş Listesi"))),"Ürün İş Listesi") -> Ürün İş Listesi | P35: Entegrasyon Suit | Q35: 65 | R35: 1 | T35: 7 | U35: 1 | W35: 74 | Z35: =Q35/W35 -> 0.87837838 | AC35: E-Fatura | AD35: 166 | AE35: 1 | AF35: 4 | AG35: 7 | AH35: 178 | AJ35: =SUM(AD35:AE35) -> 167 | AK35: =ROUNDUP(SUM(AE35:AF35),0) -> 5 | AQ35: E-Fatura | AR35: 39 | AS35: 137 | AT35: 2 | AU35: 1 | AV35: 179
A36: Story | B36: CRM-588 | C36: Done | D36: Üretim Modülü Fatura Tahsilatların İşlenmesi | E36: CRM | F36: =VLOOKUP(B36,'Türkkep Jira'!B:F,5,0) -> #N/A | G36: =IF(IFERROR(VLOOKUP(B36,'Devam Eden Sprint'!B:B,1,0),"-")=B36,"Devam Eden Sprint","-") -> - | H36: =IF(IFERROR(VLOOKUP(B36,'Gelecek Sprint'!B:B,1,0),"-")=B36,"Gelecek Sprint","-") -> - | I36: =IFERROR(IF(AND(G36="Devam Eden Sprint",H36="Gelecek Sprint"),"Devam Eden ve Gelecek Sprint",IF(G36="Devam Eden Sprint","Devam Eden Sprint",IF(H36="Gelecek Sprint","Gelecek Sprint","Ürün İş Listesi"))),"Ürün İş Listesi") -> Ürün İş Listesi | J36: 3 | P36: KEP | Q36: 42 | R36: 1 | T36: 5 | W36: 48 | Z36: =Q36/W36 -> 0.875 | AC36: Entegrasyon Suit | AD36: 95 | AE36: 1 | AF36: 1 | AG36: 2 | AH36: 99 | AJ36: =SUM(AD36:AE36) -> 96 | AK36: =ROUNDUP(SUM(AE36:AF36),0) -> 2 | AQ36: Entegrasyon Suit | AR36: 37 | AS36: 62 | AV36: 99
A37: Story | B37: CRM-589 | C37: Done | D37: Duplicate Teklif Numarası için Alarm Maili Oluşturulması | E37: CRM | F37: =VLOOKUP(B37,'Türkkep Jira'!B:F,5,0) -> #N/A | G37: =IF(IFERROR(VLOOKUP(B37,'Devam Eden Sprint'!B:B,1,0),"-")=B37,"Devam Eden Sprint","-") -> - | H37: =IF(IFERROR(VLOOKUP(B37,'Gelecek Sprint'!B:B,1,0),"-")=B37,"Gelecek Sprint","-") -> - | I37: =IFERROR(IF(AND(G37="Devam Eden Sprint",H37="Gelecek Sprint"),"Devam Eden ve Gelecek Sprint",IF(G37="Devam Eden Sprint","Devam Eden Sprint",IF(H37="Gelecek Sprint","Gelecek Sprint","Ürün İş Listesi"))),"Ürün İş Listesi") -> Ürün İş Listesi | J37: 1 | P37: Kep Assist | Q37: 48 | T37: 1 | W37: 49 | Z37: =Q37/W37 -> 0.97959184 | AC37: KEP | AD37: 50 | AE37: 3 | AH37: 53 | AJ37: =SUM(AD37:AE37) -> 53 | AK37: =ROUNDUP(SUM(AE37:AF37),0) -> 3 | AQ37: KEP | AR37: 7 | AS37: 46 | AV37: 53
A38: Story | B38: CRM-590 | C38: Done | D38: Aynı TCKN ye Ait Birden Fazla KEP Adresinin KEP IK Aktarım Süreci | E38: CRM | F38: =VLOOKUP(B38,'Türkkep Jira'!B:F,5,0) -> #N/A | G38: =IF(IFERROR(VLOOKUP(B38,'Devam Eden Sprint'!B:B,1,0),"-")=B38,"Devam Eden Sprint","-") -> - | H38: =IF(IFERROR(VLOOKUP(B38,'Gelecek Sprint'!B:B,1,0),"-")=B38,"Gelecek Sprint","-") -> - | I38: =IFERROR(IF(AND(G38="Devam Eden Sprint",H38="Gelecek Sprint"),"Devam Eden ve Gelecek Sprint",IF(G38="Devam Eden Sprint","Devam Eden Sprint",IF(H38="Gelecek Sprint","Gelecek Sprint","Ürün İş Listesi"))),"Ürün İş Listesi") -> Ürün İş Listesi | P38: KEP İK BULUT | Q38: 82 | T38: 8 | W38: 90 | Z38: =Q38/W38 -> 0.91111111 | AC38: Kep Assist | AD38: 68 | AE38: 4 | AF38: 2 | AG38: 1 | AH38: 75 | AJ38: =SUM(AD38:AE38) -> 72 | AK38: =ROUNDUP(SUM(AE38:AF38),0) -> 6 | AQ38: Kep Assist | AR38: 19 | AS38: 53 | AT38: 3 | AV38: 75
A39: Story | B39: CRM-591 | C39: Done | D39: Pasif Olan KEP Adresin Tekrar Aktif Edilmesi (UKDS) | E39: CRM | F39: =VLOOKUP(B39,'Türkkep Jira'!B:F,5,0) -> #N/A | G39: =IF(IFERROR(VLOOKUP(B39,'Devam Eden Sprint'!B:B,1,0),"-")=B39,"Devam Eden Sprint","-") -> - | H39: =IF(IFERROR(VLOOKUP(B39,'Gelecek Sprint'!B:B,1,0),"-")=B39,"Gelecek Sprint","-") -> - | I39: =IFERROR(IF(AND(G39="Devam Eden Sprint",H39="Gelecek Sprint"),"Devam Eden ve Gelecek Sprint",IF(G39="Devam Eden Sprint","Devam Eden Sprint",IF(H39="Gelecek Sprint","Gelecek Sprint","Ürün İş Listesi"))),"Ürün İş Listesi") -> Ürün İş Listesi | P39: Mobil Uygulama | Q39: 97 | T39: 10 | U39: 2 | V39: 1 | W39: 110 | Z39: =Q39/W39 -> 0.88181818 | AC39: KEP İK BULUT | AD39: 130 | AE39: 7 | AG39: 3 | AH39: 140 | AJ39: =SUM(AD39:AE39) -> 137 | AK39: =ROUNDUP(SUM(AE39:AF39),0) -> 7 | AQ39: KEP İK BULUT | AR39: 33 | AS39: 104 | AT39: 3 | AV39: 140
A40: Story | B40: CRM-592 | C40: Done | D40: Pasif Olan KEP Hesabın Tekrar Aktif Edilmesi (CRM) | E40: CRM | F40: =VLOOKUP(B40,'Türkkep Jira'!B:F,5,0) -> #N/A | G40: =IF(IFERROR(VLOOKUP(B40,'Devam Eden Sprint'!B:B,1,0),"-")=B40,"Devam Eden Sprint","-") -> - | H40: =IF(IFERROR(VLOOKUP(B40,'Gelecek Sprint'!B:B,1,0),"-")=B40,"Gelecek Sprint","-") -> - | I40: =IFERROR(IF(AND(G40="Devam Eden Sprint",H40="Gelecek Sprint"),"Devam Eden ve Gelecek Sprint",IF(G40="Devam Eden Sprint","Devam Eden Sprint",IF(H40="Gelecek Sprint","Gelecek Sprint","Ürün İş Listesi"))),"Ürün İş Listesi") -> Ürün İş Listesi | P40: Muhaberat Yönetim Sistemi | Q40: 41 | W40: 41 | Z40: =Q40/W40 -> 1 | AC40: Mobil Uygulama | AD40: 140 | AE40: 5 | AG40: 6 | AH40: 151 | AJ40: =SUM(AD40:AE40) -> 145 | AK40: =ROUNDUP(SUM(AE40:AF40),0) -> 5 | AQ40: Mobil Uygulama | AR40: 65 | AS40: 86 | AV40: 151
...

Sheet Devam Eden Sprint
A1: Issue Type | B1: Issue key | C1: Status | D1: Summary | E1: Project Name | F1: Canlıya Alma (E/H) | G1: Story Point
A2: Story | B2: EFT-2351 | C2: Development | D2: API v2.4 POC'un İncelemesi ve Olası Değişiklik Senaryolarının Değerlendirilmesi | E2: E-Fatura | G2: 13 | H2: =VLOOKUP(B2,'Ürün İş Listesi'!B:B,1,0) -> EFT-2351
A3: Story | B3: EFT-2389 | C3: Done | D3: Fatura Ürünü için 2FA Fonksiyonun Aktifleştirilmesi | E3: E-Fatura | G3: 8 | H3: =VLOOKUP(B3,'Ürün İş Listesi'!B:B,1,0) -> EFT-2389
A4: Story | B4: EFT-2395 | C4: Development | D4: IIS Sunucularında Gereksiz Dosya ve Dizinlerin Kontrolü ve Temizlenmesi | E4: E-Fatura | H4: =VLOOKUP(B4,'Ürün İş Listesi'!B:B,1,0) -> EFT-2395
A5: Story | B5: EFT-2390 | C5: Development | D5: INVOICEHISTORYID Kolon Kapasite İyileştirme Çalışması | E5: E-Fatura | G5: 5 | H5: =VLOOKUP(B5,'Ürün İş Listesi'!B:B,1,0) -> EFT-2390
A6: Bug | B6: EFT-2396 | C6: TO TEST | D6: Web Servis FaturaGönder / UBLFaturaGönder – KDV %0 Faturalar İçin İstisna Kodu Kontrolü | E6: E-Fatura | H6: =VLOOKUP(B6,'Ürün İş Listesi'!B:B,1,0) -> EFT-2396
A7: Story | B7: EDF-813 | C7: Publish | D7: e-Envanter Defteri - Şematron Kontrolü Alanı | E7: E-Defter | G7: 3 | H7: =VLOOKUP(B7,'Ürün İş Listesi'!B:B,1,0) -> EDF-813
A8: Bug | B8: EDF-814 | C8: To Do | D8: e-Defter Sözleşme Ekranında Link Güncellenmesi | E8: E-Defter | G8: 1 | H8: =VLOOKUP(B8,'Ürün İş Listesi'!B:B,1,0) -> EDF-814
A9: Story | B9: EDF-815 | C9: To Do | D9: e-Envanter Defteri - Client İmzalama İşlemleri | E9: E-Defter | G9: 5 | H9: =VLOOKUP(B9,'Ürün İş Listesi'!B:B,1,0) -> EDF-815
A10: Story | B10: EDF-822 | C10: Done | D10: Defter Ürünü için 2FA Fonksiyonun Güncellenmesi | E10: E-Defter | G10: 5 | H10: =VLOOKUP(B10,'Ürün İş Listesi'!B:B,1,0) -> EDF-822
A11: Story | B11: EDF-824 | C11: Development | D11: e-Defter Code Refactoring | E11: E-Defter | G11: 13 | H11: =VLOOKUP(B11,'Ürün İş Listesi'!B:B,1,0) -> EDF-824
A12: Story | B12: ES-306 | C12: In progress | D12: e-Saklama Code Refactoring | E12: E-Saklama | G12: 13 | H12: =VLOOKUP(B12,'Ürün İş Listesi'!B:B,1,0) -> ES-306
A13: Story | B13: ES-305 | C13: Done | D13: 2FA Fonksiyonun Güncellenmesi | E13: E-Saklama | G13: 5 | H13: =VLOOKUP(B13,'Ürün İş Listesi'!B:B,1,0) -> ES-305
A14: Story | B14: DP-292 | C14: TEST | D14: Günlük e-Belge Hata Loglarının Excel Raporu Olarak e-mail ile Gönderilmesi | E14: Destek Portal | G14: 2 | H14: =VLOOKUP(B14,'Ürün İş Listesi'!B:B,1,0) -> DP-292
A15: Story | B15: CRM-639 | D15: KEP İK Kullanıcı Yetkilendirme Modülü Entegrasyonu | E15: CRM | G15: 5 | H15: =VLOOKUP(B15,'Ürün İş Listesi'!B:B,1,0) -> CRM-639
A16: Story | B16: CRM-649 | D16: E-Fatura ve E-Arşiv Ürünleri Trafik Bilgileri Detay Görünüm | E16: CRM | G16: 3 | H16: =VLOOKUP(B16,'Ürün İş Listesi'!B:B,1,0) -> CRM-649
A17: Story | B17: CRM-682 | D17: E-Belge Entegrasyon Yönetimi Alanı Düzenleme | E17: CRM | G17: 2 | H17: =VLOOKUP(B17,'Ürün İş Listesi'!B:B,1,0) -> CRM-682
A18: Story | B18: CRM-737 | D18: Kurumsal Çözümler Zorunlu Eşitlemeler | E18: CRM | G18: 2 | H18: =VLOOKUP(B18,'Ürün İş Listesi'!B:B,1,0) -> CRM-737
A19: Story | B19: CRM-754 | D19: Kurumsal KEP Oluştur Butonunun JOB'a Bağlanması | E19: CRM | G19: 1 | H19: =VLOOKUP(B19,'Ürün İş Listesi'!B:B,1,0) -> CRM-754
A20: Story | B20: CRM-763 | D20: CRM Satış Raporuna Hatalı Yansıyan Kayıt Tiplerinin İncelenmesi | E20: CRM | G20: 5 | H20: =VLOOKUP(B20,'Ürün İş Listesi'!B:B,1,0) -> CRM-763
A21: Story | B21: CRM-766 | D21: E-Güven Servis | E21: CRM | G21: 3 | H21: =VLOOKUP(B21,'Ürün İş Listesi'!B:B,1,0) -> CRM-766
A22: Story | B22: CRM-738 | D22: KEP Opsiyonel Eşitlemeler | E22: CRM | G22: 3 | H22: =VLOOKUP(B22,'Ürün İş Listesi'!B:B,1,0) -> CRM-738
A23: Story | B23: CRM-764 | D23: KİDOS - Hesap Durum Bildirimi | E23: CRM | G23: 3 | H23: =VLOOKUP(B23,'Ürün İş Listesi'!B:B,1,0) -> CRM-764
A24: Story | B24: CRM-780 | D24: E-Güven Servis - İmza Yenileme Tarihi | E24: CRM | G24: 5 | H24: =VLOOKUP(B24,'Ürün İş Listesi'!B:B,1,0) -> CRM-780
A25: Story | B25: CRM-789 | D25: CRM&MultiKEP Ent. - Ek Geliştirme | E25: CRM | G25: 5 | H25: =VLOOKUP(B25,'Ürün İş Listesi'!B:B,1,0) -> CRM-789
A26: Story | B26: CRM-762 | D26: CRM Satış Raporu – Müşteri İlgi Seviyesi Tanımlama Kuralları | E26: CRM | G26: 2 | H26: =VLOOKUP(B26,'Ürün İş Listesi'!B:B,1,0) -> CRM-762
... A41: Story | B41: CRM-828 | D41: Halkbank Projesi - Prod Ortam Bağlantısı | E41: CRM | G41: 1 | H41: =VLOOKUP(B41,'Ürün İş Listesi'!B:B,1,0) -> CRM-828
A42: Story | B42: KEP-302 | D42: e-Güven İmzalama API Testi | E42: KEP | F42: Devam Ediyor | G42: 8 | H42: =VLOOKUP(B42,'Ürün İş Listesi'!B:B,1,0) -> KEP-302
A43: Story | B43: KEP-315 | D43: API v2.4 POC'un İncelemesi ve Olası Değişiklik Senaryolarının Değerlendirilmesi | E43: KEP | F43: Devam Ediyor | H43: =VLOOKUP(B43,'Ürün İş Listesi'!B:B,1,0) -> KEP-315
A44: Story | B44: KEP-318 | D44: Şifremi Unuttum Akışı – TCKN ve Cep Telefonu ile Adres Listeleme Servisi Geliştirilmesi | E44: KEP | F44: Tamamlandı | G44: 3 | H44: =VLOOKUP(B44,'Ürün İş Listesi'!B:B,1,0) -> KEP-318
A45: Story | B45: WIK-783 | D45: API v2.4 POC'un İncelemesi ve Olası Değişiklik Senaryolarının Değerlendirilmesi | E45: KEP İK BULUT | F45: Devam Ediyor | H45: =VLOOKUP(B45,'Ürün İş Listesi'!B:B,1,0) -> WIK-783
A46: Story | B46: WIK-793 | D46: Belge Üzerine Eklenen Doğrulama Kodu için Ölçeklendirme | E46: KEP İK BULUT | F46: Test | G46: 3 | H46: =VLOOKUP(B46,'Ürün İş Listesi'!B:B,1,0) -> WIK-793
A47: Story | B47: WIK-791 | D47: Duyuru Modülünde Çoklu Grup Seçimi ve Grup Dışı Çalışanları Ekleme Özelliği | E47: KEP İK BULUT | F47: Devam Ediyor | G47: 3 | H47: =VLOOKUP(B47,'Ürün İş Listesi'!B:B,1,0) -> WIK-791
A48: Story | B48: WIK-792 | D48: Duyurunun Birden Fazla Çalışana Bağlanabilmesi | E48: KEP İK Bulut | F48: Devan Ediyor | H48: =VLOOKUP(B48,'Ürün İş Listesi'!B:B,1,0) -> WIK-792
A49: Bug | B49: WIK-823 | D49: Yeni Dönem/Ay Açılışında Ayın Başında Mükerrer Dönem Oluşması | E49: KEP İK Bulut | F49: Devam ediyor | G49: 2 | H49: =VLOOKUP(B49,'Ürün İş Listesi'!B:B,1,0) -> WIK-823
A50: Bug | B50: WIK-824 | D50: E imza Logosunun PDF Dosyası İçerisinde Taşma Sorunu | E50: KEP İK Bulut | F50: Devam Ediyor | G50: 2 | H50: =VLOOKUP(B50,'Ürün İş Listesi'!B:B,1,0) -> WIK-824
A51: Bug | B51: WIK-825 | D51: KEP İK Dönem Servisi Metotunda Mükerer Çalışan Yüklenmesi | E51: KEP İK Bulut | F51: Test | G51: 3 | H51: =VLOOKUP(B51,'Ürün İş Listesi'!B:B,1,0) -> WIK-825
A52: Story | B52: WIK-826 | D52: Kep Delil Raporu/ Pasif Kullanıcıların Listelenmesi ve Rapor Oluşturulabilmesi | E52: KEP İK Bulut | F52: Tamamlandı | G52: 2 | H52: =VLOOKUP(B52,'Ürün İş Listesi'!B:B,1,0) -> #N/A
A53: Story | B53: WIK-827 | D53: Analiz-Çalışan Ekranı Liste Sayfasında Duyuru Detayının Pop-up Olarak Gösterilmesi | E53: KEP İK Bulut | F53: Tamamlandı | H53: =VLOOKUP(B53,'Ürün İş Listesi'!B:B,1,0) -> #N/A
A54: Story | B54: MUL-215 | D54: 2FA Fonksiyonun Geliştirilmesi | E54: MULTİKEP | F54: Devam Ediyor | G54: 3 | H54: =VLOOKUP(B54,'Ürün İş Listesi'!B:B,1,0) -> MUL-215
...

Sheet Gelecek Sprint
A1: Issue Type | B1: Issue key | C1: Status | D1: Summary | E1: Project Name | F1: Canlıya Alma (E/H) | G1: Story Point
A2: Story | B2: DP-292 | C2: TO TEST | D2: Günlük e-Belge Hata Loglarının Excel Raporu Olarak e-mail ile Gönderilmesi | E2: Destek Portal | G2: 3 | H2: =VLOOKUP(B2,'Ürün İş Listesi'!B:B,1,0) -> DP-292
A3: Story | B3: EDF-801 | C3: Development | D3: e-Defter Alanına Envanter Defteri Alanı | E3: E-Defter | G3: 13 | H3: =VLOOKUP(B3,'Ürün İş Listesi'!B:B,1,0) -> EDF-801
A4: Story | B4: EDF-808 | C4: To Do | D4: Anasayfa - Envanter Defteri Widget Alanı | E4: E-Defter | G4: 3 | H4: =VLOOKUP(B4,'Ürün İş Listesi'!B:B,1,0) -> EDF-808
A5: Story | B5: EDF-812 | C5: To Do | D5: Anasayfa - Envanter Defteri Berat Widget Alanı | E5: E-Defter | G5: 2 | H5: =VLOOKUP(B5,'Ürün İş Listesi'!B:B,1,0) -> EDF-812
A6: Story | B6: EDF-813 | C6: Publish | D6: e-Envanter Defteri - Şematron Kontrolü Alanı | E6: E-Defter | G6: 3 | H6: =VLOOKUP(B6,'Ürün İş Listesi'!B:B,1,0) -> EDF-813
A7: Bug | B7: EDF-814 | C7: To Do | D7: e-Defter Sözleşme Ekranında Link Güncellenmesi | E7: E-Defter | G7: 1 | H7: =VLOOKUP(B7,'Ürün İş Listesi'!B:B,1,0) -> EDF-814
A8: Story | B8: EDF-824 | C8: Development | D8: e-Defter Code Refactoring | E8: E-Defter | G8: 13 | H8: =VLOOKUP(B8,'Ürün İş Listesi'!B:B,1,0) -> EDF-824
A9: Story | B9: EFT-2322 | C9: To Do | D9: GİB Sicil Servis Canlı Entegresi | E9: E-Fatura | G9: 13 | H9: =VLOOKUP(B9,'Ürün İş Listesi'!B:B,1,0) -> EFT-2322
A10: Story | B10: EFT-2325 | C10: To Do | D10: GİB Sicil Servis Test Entegresi | E10: E-Fatura | G10: 8 | H10: =VLOOKUP(B10,'Ürün İş Listesi'!B:B,1,0) -> EFT-2325
A11: Story | B11: EFT-2351 | C11: Development | D11: API v2.4 POC'un İncelemesi ve Olası Değişiklik Senaryolarının Değerlendirilmesi | E11: E-Fatura | G11: 13 | H11: =VLOOKUP(B11,'Ürün İş Listesi'!B:B,1,0) -> EFT-2351
A12: Story | B12: EFT-2390 | C12: Development | D12: INVOICEHISTORYID Kolon Kapasite İyileştirme Çalışması | E12: E-Fatura | G12: 5 | H12: =VLOOKUP(B12,'Ürün İş Listesi'!B:B,1,0) -> EFT-2390
A13: Story | B13: EFT-2395 | C13: Development | D13: IIS Sunucularında Gereksiz Dosya ve Dizinlerin Kontrolü ve Temizlenmesi | E13: E-Fatura | H13: =VLOOKUP(B13,'Ürün İş Listesi'!B:B,1,0) -> EFT-2395
A14: Bug | B14: EFT-2396 | C14: TO TEST | D14: Web Servis FaturaGönder / UBLFaturaGönder – KDV %0 Faturalar İçin İstisna Kodu Kontrolü | E14: E-Fatura | H14: =VLOOKUP(B14,'Ürün İş Listesi'!B:B,1,0) -> EFT-2396
A15: Story | B15: EFT-2397 | C15: To Do | D15: GİB - e-Fatura Paketi Güncelleme(V 1.42) | E15: E-Fatura | G15: 1 | H15: =VLOOKUP(B15,'Ürün İş Listesi'!B:B,1,0) -> EFT-2397
A16: Story | B16: EFT-2398 | C16: To Do | D16: Portal - Nace Kodu - 555 İstisna | E16: E-Fatura | H16: =VLOOKUP(B16,'Ürün İş Listesi'!B:B,1,0) -> EFT-2398
A17: Story | B17: EFT-2399 | C17: To Do | D17: WebServis - Nace Kodu - 555 İstisna | E17: E-Fatura | H17: =VLOOKUP(B17,'Ürün İş Listesi'!B:B,1,0) -> EFT-2399
A18: Story | B18: EFT-2400 | C18: Development | D18: Nace Kodu - Veritabanına Yeni Mükellef Detay Tablosu Eklenmesi | E18: E-Fatura | G18: 3 | H18: =VLOOKUP(B18,'Ürün İş Listesi'!B:B,1,0) -> EFT-2400
A19: Story | B19: EFT-2401 | C19: To Do | D19: Konnektör - Nace Kodu - 555 İstisna | E19: E-Fatura | H19: =VLOOKUP(B19,'Ürün İş Listesi'!B:B,1,0) -> EFT-2401
A20: Story | B20: CRM-639 | C20: TO TEST | D20: KEP İK Kullanıcı Yetkilendirme Modülü Entegrasyonu | E20: CRM | G20: 5 | H20: =VLOOKUP(B20,'Ürün İş Listesi'!B:B,1,0) -> CRM-639
A21: Story | B21: CRM-649 | C21: TO TEST | D21: E-Fatura ve E-Arşiv Ürünleri Trafik Bilgileri Detay Görünüm | E21: CRM | G21: 3 | H21: =VLOOKUP(B21,'Ürün İş Listesi'!B:B,1,0) -> CRM-649
A22: Story | B22: CRM-682 | C22: TO TEST | D22: E-Belge Entegrasyon Yönetimi Alanı Düzenleme | E22: CRM | G22: 2 | H22: =VLOOKUP(B22,'Ürün İş Listesi'!B:B,1,0) -> CRM-682
A23: Story | B23: CRM-754 | C23: TO TEST | D23: Kurumsal KEP Oluştur Butonunun JOB'a Bağlanması | E23: CRM | G23: 1 | H23: =VLOOKUP(B23,'Ürün İş Listesi'!B:B,1,0) -> CRM-754
A24: Story | B24: CRM-763 | C24: TO TEST | D24: CRM Satış Raporuna Hatalı Yansıyan Kayıt Tiplerinin İncelenmesi | E24: CRM | G24: 5 | H24: =VLOOKUP(B24,'Ürün İş Listesi'!B:B,1,0) -> CRM-763
A25: Story | B25: CRM-766 | C25: TO TEST | D25: E-Güven Servis | E25: CRM | G25: 3 | H25: =VLOOKUP(B25,'Ürün İş Listesi'!B:B,1,0) -> CRM-766
A26: Story | B26: CRM-737 | C26: TO TEST | D26: Kurumsal Çözümler Zorunlu Eşitlemeler | E26: CRM | G26: 2 | H26: =VLOOKUP(B26,'Ürün İş Listesi'!B:B,1,0) -> CRM-737
A27: Story | B27: CRM-738 | C27: TO TEST | D27: KEP Opsiyonel Eşitlemeler | E27: CRM | G27: 3 | H27: =VLOOKUP(B27,'Ürün İş Listesi'!B:B,1,0) -> CRM-738
A28: Story | B28: CRM-764 | C28: TO TEST | D28: KİDOS - Hesap Durum Bildirimi | E28: CRM | G28: 3 | H28: =VLOOKUP(B28,'Ürün İş Listesi'!B:B,1,0) -> CRM-764
A29: Story | B29: CRM-780 | C29: TO TEST | D29: E-Güven Servis - İmza Yenileme Tarihi | E29: CRM | G29: 5 | H29: =VLOOKUP(B29,'Ürün İş Listesi'!B:B,1,0) -> CRM-780
A30: Story | B30: CRM-789 | C30: TO TEST | D30: CRM&MultiKEP Ent. - Ek Geliştirme | E30: CRM | G30: 5 | H30: =VLOOKUP(B30,'Ürün İş Listesi'!B:B,1,0) -> CRM-789
A31: Story | B31: CRM-762 | C31: TO TEST | D31: CRM Satış Raporu – Müşteri İlgi Seviyesi Tanımlama Kuralları | E31: CRM | G31: 2 | H31: =VLOOKUP(B31,'Ürün İş Listesi'!B:B,1,0) -> CRM-762
... A43: Story | B43: CRM-827 | C43: To Do | D43: Halkbank Projesi - Statü Kodu Senaryo | E43: CRM | G43: 2 | H43: =VLOOKUP(B43,'Ürün İş Listesi'!B:B,1,0) -> CRM-827
A44: Bug | B44: WIK-832 | D44: Çalışan Ekle- Tek Başvuru Ekleme Adımı Karakter ve Parametre Kontrolü | E44: KEP İK BULUT | G44: 2 | H44: =VLOOKUP(B44,'Ürün İş Listesi'!B:B,1,0) -> WIK-832
A45: Bug | B45: WIK-834 | D45: KEP Delil Raporlarının Sıralanması | E45: KEP İK BULUT | G45: 1 | H45: =VLOOKUP(B45,'Ürün İş Listesi'!B:B,1,0) -> WIK-834
A46: Bug | B46: WIK-833 | D46: Sistem Ayarları Sayfasında ''Kaydet'' Aşamasının Uyarısı | E46: KEP İK BULUT | G46: 1 | H46: =VLOOKUP(B46,'Ürün İş Listesi'!B:B,1,0) -> WIK-833
A47: Bug | B47: UKDS-228 | D47: Kampanya Başvuru Sayfası Cep Telefonu Numarası Girişi | E47: UKDS | G47: 2 | H47: =VLOOKUP(B47,'Ürün İş Listesi'!B:B,1,0) -> UKDS-228
A48: Story | B48: UKDS-229 | D48: IKENTEGRATORBIREYSEL- Ön Başvuru Süreç Linkinde Firma Bilgilerinin Gösterimi | E48: UKDS | G48: 3 | H48: =VLOOKUP(B48,'Ürün İş Listesi'!B:B,1,0) -> UKDS-229
A49: Story | B49: IEU-264 | D49: Entegrasyon Suit - UKDS Web Servis Entegrasyonunun Teknik Dokümantasyonunun Hazırlanması | E49: Entegrasyon Suit | H49: =VLOOKUP(B49,'Ürün İş Listesi'!B:B,1,0) -> IEU-264
A50: Story | B50: KA-1588 | D50: Prod ortamda Türkçe olmayan kelimelerin tespit edilmesi ve Türkçeleştirilmesi | E50: Kep Assist | H50: =VLOOKUP(B50,'Ürün İş Listesi'!B:B,1,0) -> KA-1588
A51: Story | B51: IEU-342 | D51: Utify Servisi: Tebligat Dönüşleri Detaylı KEP Adresi Raporu ve Adetleri (Başarısız Olanlar) Eklenmesi | E51: Entegrasyon Suit | G51: 2 | H51: =VLOOKUP(B51,'Ürün İş Listesi'!B:B,1,0) -> IEU-342
...

Sheet Türkkep Jira
A1: Summary | B1: Issue key | C1: Issue id | D1: Parent id | E1: Issue Type | F1: Status | G1: Project key | H1: Project name | I1: Project type | J1: Project lead | K1: Project description | L1: Project url | M1: Priority | N1: Resolution | O1: Assignee | P1: Reporter | Q1: Creator | R1: Created | S1: Updated | T1: Last Viewed | U1: Resolved | V1: Fix Version/s | W1: Component/s | X1: Due Date | Y1: Votes | Z1: Labels | AA1: Description | AB1: Environment | AC1: Watchers | AD1: Watchers_1 | AE1: Watchers_2 | AF1: Watchers_3 | AG1: Watchers_4 | AH1: Log Work | AI1: Log Work_5 | AJ1: Log Work_6 | AK1: Log Work_7 | AL1: Log Work_8 | AM1: Log Work_9 | AN1: Log Work_10 | AO1: Log Work_11 | AP1: Log Work_12 | AQ1: Log Work_13 | AR1: Log Work_14 | AS1: Log Work_15 | AT1: Log Work_16 | AU1: Log Work_17 | AV1: Log Work_18 | AW1: Log Work_19 | AX1: Log Work_20 | AY1: Log Work_21 | AZ1: Log Work_22 | BA1: Log Work_23 | BB1: Log Work_24 | BC1: Log Work_25 | BD1: Log Work_26 | BE1: Log Work_27 | BF1: Log Work_28 | BG1: Log Work_29 | BH1: Log Work_30 | BI1: Log Work_31 | BJ1: Log Work_32 | BK1: Log Work_33 | BL1: Log Work_34 | BM1: Log Work_35 | BN1: Log Work_36 | BO1: Log Work_37 | BP1: Original Estimate | BQ1: Remaining Estimate | BR1: Time Spent | BS1: Work Ratio | BT1: Σ Original Estimate | BU1: Σ Remaining Estimate | BV1: Σ Time Spent | BW1: Security Level | BX1: Outward issue link (Cloners) | BY1: Outward issue link (Relates) | BZ1: Attachment | CA1: Attachment_38 | CB1: Attachment_39 | CC1: Attachment_40 | CD1: Attachment_41 | CE1: Attachment_42 | CF1: Attachment_43 | CG1: Attachment_44 | CH1: Attachment_45 | CI1: Attachment_46 | CJ1: Custom field (Analyst) | CK1: Custom field (Başlama Tarihi) | CL1: Custom field (Epic Color) | CM1: Custom field (Epic Link) | CN1: Custom field (Epic Name) | CO1: Custom field (Epic Status) | CP1: Custom field (Ortak - Kayda Atanan) | CQ1: Custom field (Ortak - Kaydı Açan) | CR1: Custom field (Pending Reason) | CS1: Custom field (Product Owner) | CT1: Custom field (Rank) | CU1: Sprint | CV1: Sprint_47 | CW1: Sprint_48 | CX1: Sprint_49 | CY1: Sprint_50 | CZ1: Sprint_51 | DA1: Sprint_52 | DB1: Sprint_53 | DC1: Sprint_54 | DD1: Sprint_55 | DE1: Sprint_56 | DF1: Sprint_57 | DG1: Sprint_58 | DH1: Sprint_59 | DI1: Custom field (Story Points) | DJ1: Custom field (Talep Sahibi - CRM) | DK1: Custom field (Tester) | DL1: Comment | DM1: Comment_60 | DN1: Comment_61 | DO1: Comment_62 | DP1: Comment_63 | DQ1: Comment_64 | DR1: Comment_65 | DS1: Comment_66 | DT1: Comment_67 | DU1: Comment_68 | DV1: Comment_69 | DW1: Comment_70 | DX1: Comment_71 | DY1: Comment_72 | DZ1: Comment_73 | EA1: Comment_74 | EB1: Comment_75 | EC1: Comment_76 | ED1: Comment_77 | EE1: Comment_78 | EF1: Comment_79 | EG1: Comment_80 | EH1: Comment_81
A2: n8n ile HTML/XML Parse (BeautifulSoup Benzeri) Yetkinlik Araştırması | B2: YZCK-46 | C2: 23133 | E2: Task | F2: Done | G2: YZCK | H2: Yapay Zeka Destekli Çağrı Karşılama | I2: software | J2: elvan.gurler | M2: Medium | N2: Done | O2: basak.ayverdi | P2: elvan.gurler | Q2: elvan.gurler | R2: 46090.47 | S2: 46097.688 | T2: 46100.369 | U2: 46097.688 | Y2: 0 | AA2: n8n platformunda web sayfalarından veri çekme ve HTML/XML parse işlemlerinin yapılabilirliği araştırılacaktır. Bu kapsamda Python kütüphanesi olan Beautiful Soup ile yapılan işlemlerin n8n üzerinde ** benzeri yöntemlerle gerçekleştirilip gerçekleştirilemeyeceği incelenecektir._x000D_ _x000D_ Araştırma kapsamında:_x000D_ * Web sayfasından veri çekme (HTTP Request)_x000D_ _x000D_ * HTML içinden veri parse etme (selector kullanımı)_x000D_ _x000D_ * Karmaşık HTML yapılarının işlenebilirliği_x000D_ _x000D_ * Gerekirse JavaScript veya harici servis kullanımı_x000D_ _x000D_ konuları değerlendirilerek teknik yapılabilirlik analizi yapılacaktır. | AC2: elvan.gurler | AH2: n8n platformunda web sayfalarından veri çekme ve HTML/XML parse işlemlerinin yapılabilirliği araştırıldı._x000D_ HTTP Request kullanarak sayfa içeriğinin alınması, CSS selector ile veri çıkarılması ve karmaşık HTML yapılarını işleme yöntemleri incelendi._x000D_ Dinamik web sayfaları için harici scraping servislerinin (Browserless, ScrapingBee vb.) kullanım senaryoları değerlendirildi._x000D_ Elde edilen bulgular doğrultusunda teknik değerlendirme raporu hazırlanarak dokümante edildi.;09/Mar/26 4:42 PM;basak.ayverdi;21600 | AI2: n8n kullanılarak rakip ürün takip sistemi kurulmasının teknik fizibilitesi araştırıldı ve sistem mimarisi ile önerilen workflow’u içeren teknik dokümantasyon hazırlandı.;10/Mar/26 5:08 PM;basak.ayverdi;21600 | BQ2: 0 | BR2: 43200 | BU2: 0 | BV2: 43200 | BZ2: 09/Mar/26 4:40 PM;basak.ayverdi;bsoup_n8n değerlendirme.docx;http://192.168.124.186:8080/secure/attachment/15990/bsoup_n8n+de%C4%9Ferlendirme.docx | CA2: 10/Mar/26 5:09 PM;basak.ayverdi;rakip_urun_takip_sistemi.docx;http://192.168.124.186:8080/secure/attachment/16018/rakip_urun_takip_sistemi.docx | CT2: 0|i01ef0:w | CU2: YZCK Sprint 4
A3: Değerlendirme ve Cevap Alınmayan Soruların İletildiği Workflow İncelenmesi | B3: YZCK-45 | C3: 23112 | E3: Bug | F3: Done | G3: YZCK | H3: Yapay Zeka Destekli Çağrı Karşılama | I3: software | J3: elvan.gurler | M3: Medium | N3: Done | O3: omer.saritoy | P3: elvan.gurler | Q3: elvan.gurler | R3: 46087.566 | S3: 46091.647 | T3: 46100.369 | U3: 46091.647 | Y3: 0 | AA3: Değerlendirme ve cevap alınmayan soruların iletildiği workflowda cevaplandığı halde sorular cevaplanmamış gibi dönüyor. Tekrar düzenleme yapılması gerekmektedir. | AC3: elvan.gurler | AH3: Bota gelen unanswered questions workflow’unda tespit edilen hata doğrultusunda gerekli güncelleme yapılmış ve testleri gerçekleştirilmiştir.;06/Mar/26 4:29 PM;basak.ayverdi;10800 | AI3: Unanswerdquestion wf da sorular cevaplanmasına rağmen cevaplanmadı şeklinde excel verilerine eklenmiş bu hata üzerinde çalışmalar yapıldı ve giderildi .Test aşamasına kadar getirildi ;06/Mar/26 4:33 PM;omer.saritoy;10800 | AJ3: İlgili Bug Tespit edilip sorun giderildi ;10/Mar/26 3:30 PM;omer.saritoy;10800 | BQ3: 0 | BR3: 32400 | BU3: 0 | BV3: 32400 | CT3: 0|i01ef6:5i | CU3: YZCK Sprint 4
A4: İK AI Asistanı – Araştırma ve Kapsam Belirleme | B4: YZCK-44 | C4: 23111 | E4: Story | F4: Done | G4: YZCK | H4: Yapay Zeka Destekli Çağrı Karşılama | I4: software | J4: elvan.gurler | M4: Medium | N4: Done | O4: basak.ayverdi | P4: elvan.gurler | Q4: elvan.gurler | R4: 46087.557 | S4: 46090.371 | T4: 46100.369 | U4: 46090.371 | Y4: 0 | AA4: Dün yapılan YK toplantısında İK süreçlerini destekleyecek bir AI asistan geliştirilmesi ihtiyacı gündeme gelmiştir. Bu kapsamda, İK için geliştirilebilecek AI asistanın fonksiyonları ve MVP kapsamında hangi modüllerin önceliklendirileceği konusunda ön araştırma yapılacaktır._x000D_ _x000D_ Araştırma kapsamında:_x000D_ * İK AI asistanı kullanım senaryolarının incelenmesi (Recruitment AI, Employee Experience, People Analytics)_x000D_ _x000D_ * Piyasadaki benzer çözümlerin (ATS, HR AI araçları vb.) analiz edilmesi_x000D_ _x000D_ * MVP için önerilen modüllerin belirlenmesi (İşe alım ön eleme ve çalışan SSS asistanı)_x000D_ _x000D_ * Kurum içi sistemlerle olası entegrasyonların değerlendirilmesi (ERP, Teams vb.) | AC4: basak.ayverdi | AD4: elvan.gurler | AH4: Agent araştırma taskı kapsamında geliştirilebilecek feature’ların değerlendirilmesi amacıyla toplantı öncesinde dokümantasyon hazırlanmış ve ilgili toplantıya katılım sağlanmıştır.;06/Mar/26 4:27 PM;basak.ayverdi;10800 | AI4: IK agent üzeirne araştırmalar yapıldı . Bir IK nelere ihtiyaç duyar ve ai ile nasıl işleri hafifler üzerine araştırmalar yapıldı ;06/Mar/26 4:34 PM;omer.saritoy;7200 | AJ4: türk pazarındaki ürünler incelendi;09/Mar/26 8:54 AM;basak.ayverdi;3600 | BQ4: 0 | BR4: 21600 | BU4: 0 | BV4: 21600 | BZ4: 06/Mar/26 4:28 PM;basak.ayverdi;HR AI Agent – Capability Overview.pdf;http://192.168.124.186:8080/secure/attachment/15979/HR+AI+Agent+%E2%80%93+Capability+Overview.pdf | CT4: 0|i01ef6:5 | CU4: YZCK Sprint 4 | DL4: 09/Mar/26 8:53 AM;basak.ayverdi;https://www.hiri.ai/https://www.hiri.ai/_x000D_ https://ikai.com.tr/_x000D_ https://www.layersup.com/tr_x000D_ https://www.cbot.ai/_x000D_
